<?xml version="1.0"?>
<robot xmlns:xacro="http://www.ros.org/wiki/xacro" >

    <xacro:include filename="inertial_macros.xacro"/>

    <!-- BASE LINK -->

    <link name="base_link">
          <inertial>
    <origin xyz="0.00024062344110785007 -0.00531572402780089 -0.10823524150435863" rpy="0 0 0"/>
    <mass value="19.729806517747196"/>
    <inertia ixx="0.871968" iyy="0.872497" izz="1.726537" ixy="0.000808" iyz="0.001686" ixz="0.000142"/>
  </inertial>
  <visual>
    <origin xyz="0 0 0" rpy="0 0 0"/>
    <material name="silver"/>
  </visual>
  <collision>
    <origin xyz="0 0 0" rpy="0 0 0"/>
  </collision>
    </link>


    <!-- CHASSIS LINK -->

    <joint name="chassis_joint" type="fixed">
        <parent link="base_link"/>
        <child link="chassis"/>
        <origin xyz="-0.1 0 0"/>
    </joint>

    <link name="chassis">
        <visual>
            <origin xyz="0.15 0 0.075"/>
            <geometry>
                <box size="0.3 0.3 0.15"/>
            </geometry>
            <material name="white"/>
        </visual>
        <collision>
            <origin xyz="0.15 0 0.075"/>
            <geometry>
                <box size="0.3 0.3 0.15"/>
            </geometry>
        </collision>
        <xacro:inertial_box mass="2.0" x="0.3" y="0.3" z="0.15">
            <origin xyz="0.15 0 0.075" rpy="0 0 0"/>
        </xacro:inertial_box>
    </link>
    
    <!-- LEFT WHEEL LINK -->

    <joint name="left_wheel_joint" type="continuous">
        <parent link="base_link"/>
        <child link="left_wheel"/>
        <origin xyz="0 0.175 0" rpy="-${pi/2} 0 0" />
        <axis xyz="0 0 1"/>
    </joint>

    <link name="left_wheel">
        <visual>
            <geometry>
                <cylinder radius="0.05" length="0.04"/>
            </geometry>
            <material name="blue"/>
        </visual>
        <collision>
            <geometry>
                <cylinder radius="0.05" length="0.04"/>
            </geometry>
        </collision>
        <xacro:inertial_cylinder mass="0.1" length="0.04" radius="0.05">
            <origin xyz="0 0 0" rpy="0 0 0"/>
        </xacro:inertial_cylinder>
    </link>

    <!-- RIGHT WHEEL LINK -->

    <joint name="right_wheel_joint" type="continuous">
        <parent link="base_link"/>
        <child link="right_wheel"/>
        <origin xyz="0 -0.175 0" rpy="${pi/2} 0 0" />
        <axis xyz="0 0 -1"/>
    </joint>

    <link name="right_wheel">
        <visual>
            <geometry>
                <cylinder radius="0.05" length="0.04"/>
            </geometry>
            <material name="blue"/>
        </visual>
        <collision>
            <geometry>
                <cylinder radius="0.05" length="0.04"/>
            </geometry>
        </collision>
        <xacro:inertial_cylinder mass="0.1" length="0.04" radius="0.05">
            <origin xyz="0 0 0" rpy="0 0 0"/>
        </xacro:inertial_cylinder>
    </link>

    <!-- CASTER WHEEL LINK -->

    <joint name="caster_wheel_joint" type="fixed">
        <parent link="chassis"/>
        <child link="caster_wheel"/>
        <origin xyz="0.24 0 0"/>
    </joint>


    <link name="caster_wheel">
        <visual>
            <geometry>
                <sphere radius="0.05"/>
            </geometry>
            <material name="black"/>
        </visual>
        <collision>
            <geometry>
                <sphere radius="0.05"/>
            </geometry>
        </collision>
        <xacro:inertial_sphere mass="0.5" radius="0.05">
            <origin xyz="0.24 0 0" rpy="0 0 0"/>
        </xacro:inertial_sphere>
    </link>


    <xacro:property name="camera_link" value="0.05" /> <!-- Size of square 'camera' box -->

    <joint name="camera_joint" type="fixed">
        <axis xyz="0 1 0" />
        <origin xyz="0.2 0.0 0.1" rpy="0 0 0"/>
        <parent link="base_link"/>
        <child link="vanir/base_link/depth_camera1"/>
    </joint>

    <!-- Camera -->
    <link name="vanir/base_link/depth_camera1">
        <collision>
        <origin xyz="0 0 0" rpy="0 0 0"/>
        <geometry>
        <box size="${camera_link} ${camera_link} ${camera_link}"/>
        </geometry>
        </collision>

        <visual>
        <origin xyz="0 0 0" rpy="0 0 0"/>
        <geometry>
        <box size="${camera_link} ${camera_link} ${camera_link}"/>
        </geometry>
        <material name="red"/>
        </visual>


        <inertial>
        <mass value="1e-5" />
        <origin xyz="0 0 0" rpy="0 0 0"/>
        <inertia ixx="1e-6" ixy="0" ixz="0" iyy="1e-6" iyz="0" izz="1e-6" />
        </inertial>
    </link>


 <!-- LIDAR SENSOR -->
    <joint name="lidar_joint" type="fixed">
        <parent link="base_link"/>
        <child link="vanir/base_link/gpu_lidar"/>
        <origin xyz="0.04 0 0.18" rpy="0 0 0"/>
    </joint>

    <link name="vanir/base_link/gpu_lidar">
        <visual>
            <geometry>
                <cylinder radius="0.03" length="0.06"/>
            </geometry>
            <material name="black"/>
        </visual>
        <collision>
            <geometry>
                <cylinder radius="0.03" length="0.06"/>
            </geometry>
        </collision>
        <inertial>
            <mass value="0.05"/>
            <origin xyz="0 0 0" rpy="0 0 0"/>
            <inertia ixx="1e-6" ixy="0" ixz="0" iyy="1e-6" iyz="0" izz="1e-6"/>
        </inertial>
    </link>
    
</robot>
